<mujoco model="hopper">
    <option timestep="0.005" integrator="Euler" o_solref="0.1 1"/>
    <compiler angle="degree" coordinate="global" inertiafromgeom="true"/>
    <default>
        <joint armature="1" damping="1" limited="true"/>
        <geom conaffinity="1" condim="1" contype="1" margin="0.001" material="geom" solimp=".8 .8 .01" solref=".02 1"/>
        <motor ctrllimited="true" ctrlrange="-.4 .4"/>
    </default>
    <visual>
        <rgba haze="0.15 0.25 0.35 1"/>
        <quality shadowsize="2048"/>
        <map stiffness="700" shadowscale="0.5" fogstart="10" fogend="15" zfar="40" haze="0.3"/>
    </visual>

    <asset>
        <texture type="skybox" builtin="gradient" rgb1="0.3 0.5 0.7" rgb2="0 0 0" width="512" height="512"/>
        <texture name="texplane" type="2d" builtin="checker" rgb1=".2 .3 .4" rgb2=".1 0.15 0.2"
            width="512" height="512" mark="cross" markrgb=".8 .8 .8"/>
        <texture builtin="flat" height="1278" mark="cross" markrgb="1 1 1" name="texgeom" random="0.01" rgb1="0.8 0.6 0.4" rgb2="0.8 0.6 0.4" type="cube" width="127"/>
        <material name="matplane" reflectance="0.3" texture="texplane" texrepeat="1 1" texuniform="true"/>
        <material name="geom" texture="texgeom" texuniform="true"/>
    </asset>

    <worldbody>
        <light directional="true" diffuse=".4 .4 .4" specular="0.1 0.1 0.1" pos="0 0 5.0" dir="0 0 -1" castshadow="false"/>
        <light directional="true" diffuse=".6 .6 .6" specular="0.2 0.2 0.2" pos="0 0 4" dir="0 0 -1"/>
        <geom name="ground" type="plane" size="0 0 1" pos="0 0 0" quat="1 0 0 0" material="matplane" conaffinity="1" condim="3" />

        <body name="torso" pos="0 0 1.25">
            <joint armature="0" axis="1 0 0" damping="0" limited="false" name="rootx" pos="0 0 0" stiffness="0" type="slide"/>
            <joint armature="0" axis="0 0 1" damping="0" limited="false" name="rootz" pos="0 0 0" ref="1.25" stiffness="0" type="slide"/>
            <joint armature="0" axis="0 1 0" damping="0" limited="false" name="rooty" pos="0 0 1.25" stiffness="0" type="hinge"/>
            <geom friction="0.9" fromto="0 0 1.45 0 0 1.05" name="torso_geom" size="0.05" type="capsule"/>
            <body name="thigh" pos="0 0 1.05">
                <joint axis="0 -1 0" name="thigh_joint" pos="0 0 1.05" range="-150 0" type="hinge"/>
                <geom friction="0.9" fromto="0 0 1.05 0 0 0.6" name="thigh_geom" size="0.05" type="capsule"/>
                <body name="leg" pos="0 0 0.35">
                    <joint axis="0 -1 0" name="leg_joint" pos="0 0 0.6" range="-150 0" type="hinge"/>
                    <geom friction="0.9" fromto="0 0 0.6 0 0 0.1" name="leg_geom" size="0.04" type="capsule"/>
                    <body name="foot" pos="0.13/2 0 0.1">
                        <joint axis="0 -1 0" name="foot_joint" pos="0 0 0.1" range="-45 45" type="hinge"/>
                        <geom friction="2.0" fromto="-0.13 0 0.1 0.26 0 0.1" name="foot_geom" size="0.06" type="capsule"/>
                    </body>
                </body>
            </body>
        </body>
    </worldbody>
    <actuator>
        <motor ctrllimited="true" ctrlrange="-1.0 1.0" gear="200.0" joint="thigh_joint"/>
        <motor ctrllimited="true" ctrlrange="-1.0 1.0" gear="200.0" joint="leg_joint"/>
        <motor ctrllimited="true" ctrlrange="-1.0 1.0" gear="200.0" joint="foot_joint"/>
    </actuator>

</mujoco>
